<?xml version="1.0" encoding="utf-8"?>
<!-- This URDF was automatically created by SolidWorks to URDF Exporter! Originally created by Stephen Brawner (brawner@gmail.com) 
     Commit Version: 1.6.0-1-g15f4949  Build Version: 1.6.7594.29634
     For more information, please see http://wiki.ros.org/sw_urdf_exporter -->
<robot
  name="leg-2">
  <link
    name="base_link">
    <inertial>
      <origin
        xyz="-4.06369711145049E-09 -6.53076676071507E-10 0.00655119521484451"
        rpy="0 0 0" />
      <mass
        value="0.0603574048047682" />
      <inertia
        ixx="2.62795167194068E-05"
        ixy="1.08062986106813E-12"
        ixz="4.29652646551279E-12"
        iyy="3.23876165617027E-05"
        iyz="3.99812665692441E-13"
        izz="5.36673495130944E-05" />
    </inertial>
    <visual>
      <origin
        xyz="0 0 0"
        rpy="0 0 0" />
      <geometry>
        <mesh
          filename="package://leg-2/meshes/base_link.STL" />
      </geometry>
      <material
        name="">
        <color
          rgba="1 1 1 1" />
      </material>
    </visual>
    <collision>
      <origin
        xyz="0 0 0"
        rpy="0 0 0" />
      <geometry>
        <mesh
          filename="package://leg-2/meshes/base_link.STL" />
      </geometry>
    </collision>
  </link>
  <link
    name="L_L_0">
    <inertial>
      <origin
        xyz="-0.00500044767930677 -8.03686567435458E-08 -3.69876562988924E-07"
        rpy="0 0 0" />
      <mass
        value="0.00111252650071424" />
      <inertia
        ixx="5.86374551035033E-08"
        ixy="7.32232501706718E-13"
        ixz="-1.71378477470593E-12"
        iyy="1.47185849965676E-08"
        iyz="-8.00224605316878E-13"
        izz="5.70070170387329E-08" />
    </inertial>
    <visual>
      <origin
        xyz="0 0 0"
        rpy="0 0 0" />
      <geometry>
        <mesh
          filename="package://leg-2/meshes/L_L_0.STL" />
      </geometry>
      <material
        name="">
        <color
          rgba="1 1 1 1" />
      </material>
    </visual>
    <collision>
      <origin
        xyz="0 0 0"
        rpy="0 0 0" />
      <geometry>
        <mesh
          filename="package://leg-2/meshes/L_L_0.STL" />
      </geometry>
    </collision>
  </link>
  <joint
    name="J_L_0"
    type="continuous">
    <origin
      xyz="0 -0.035 0.0300000000000001"
      rpy="-0.279854049721946 0 -1.5707963267949" />
    <parent
      link="base_link" />
    <child
      link="L_L_0" />
    <axis
      xyz="1 0 0" />
  </joint>
  <link
    name="L_L_1">
    <inertial>
      <origin
        xyz="2.56739074444567E-15 0.0074999999999992 -8.04911692853238E-16"
        rpy="0 0 0" />
      <mass
        value="0.00642920367320511" />
      <inertia
        ixx="7.7370483969244E-07"
        ixy="-2.64697796016969E-23"
        ixz="-7.51703564774716E-23"
        iyy="5.72792224904781E-07"
        iyz="-5.75280396845419E-24"
        izz="8.32798685348823E-07" />
    </inertial>
    <visual>
      <origin
        xyz="0 0 0"
        rpy="0 0 0" />
      <geometry>
        <mesh
          filename="package://leg-2/meshes/L_L_1.STL" />
      </geometry>
      <material
        name="">
        <color
          rgba="1 1 1 1" />
      </material>
    </visual>
    <collision>
      <origin
        xyz="0 0 0"
        rpy="0 0 0" />
      <geometry>
        <mesh
          filename="package://leg-2/meshes/L_L_1.STL" />
      </geometry>
    </collision>
  </link>
  <joint
    name="J_L_1"
    type="continuous">
    <origin
      xyz="-0.00500000000000003 0 0"
      rpy="1.5707963267949 0 -1.5707963267949" />
    <parent
      link="L_L_0" />
    <child
      link="L_L_1" />
    <axis
      xyz="1 0 0" />
  </joint>
  <link
    name="L_L_2">
    <inertial>
      <origin
        xyz="0.0829352552189961 -0.00577871243285216 -1.04083408558608E-16"
        rpy="0 0 0" />
      <mass
        value="0.0162098836233209" />
      <inertia
        ixx="2.40381887534248E-06"
        ixy="6.16592737719074E-06"
        ixz="3.48419816267515E-22"
        iyy="3.53395888356251E-05"
        iyz="-9.33045868568433E-22"
        izz="3.74765154762597E-05" />
    </inertial>
    <visual>
      <origin
        xyz="0 0 0"
        rpy="0 0 0" />
      <geometry>
        <mesh
          filename="package://leg-2/meshes/L_L_2.STL" />
      </geometry>
      <material
        name="">
        <color
          rgba="1 1 1 1" />
      </material>
    </visual>
    <collision>
      <origin
        xyz="0 0 0"
        rpy="0 0 0" />
      <geometry>
        <mesh
          filename="package://leg-2/meshes/L_L_2.STL" />
      </geometry>
    </collision>
  </link>
  <joint
    name="J_L_2"
    type="continuous">
    <origin
      xyz="0 0.01 0"
      rpy="-3.14159265358979 0 1.5707963267949" />
    <parent
      link="L_L_1" />
    <child
      link="L_L_2" />
    <axis
      xyz="1 0 0" />
  </joint>
  <link
    name="L_R_0">
    <inertial>
      <origin
        xyz="0.00499955232069328 -8.03686492842348E-08 -3.6987656351628E-07"
        rpy="0 0 0" />
      <mass
        value="0.00111252650071424" />
      <inertia
        ixx="5.86374551035033E-08"
        ixy="7.32232501485636E-13"
        ixz="-1.71378477464577E-12"
        iyy="1.47185849965676E-08"
        iyz="-8.00224605373333E-13"
        izz="5.70070170387329E-08" />
    </inertial>
    <visual>
      <origin
        xyz="0 0 0"
        rpy="0 0 0" />
      <geometry>
        <mesh
          filename="package://leg-2/meshes/L_R_0.STL" />
      </geometry>
      <material
        name="">
        <color
          rgba="1 1 1 1" />
      </material>
    </visual>
    <collision>
      <origin
        xyz="0 0 0"
        rpy="0 0 0" />
      <geometry>
        <mesh
          filename="package://leg-2/meshes/L_R_0.STL" />
      </geometry>
    </collision>
  </link>
  <joint
    name="J_R_0"
    type="continuous">
    <origin
      xyz="0 0.0249999999999999 0.03"
      rpy="0.279854049721946 0 1.5707963267949" />
    <parent
      link="base_link" />
    <child
      link="L_R_0" />
    <axis
      xyz="1 0 0" />
  </joint>
  <link
    name="L_R_1">
    <inertial>
      <origin
        xyz="-4.87804241444678E-15 0.00749999999999895 7.63278329429795E-16"
        rpy="0 0 0" />
      <mass
        value="0.0064292036732051" />
      <inertia
        ixx="7.73704839692439E-07"
        ixy="2.24993126614424E-22"
        ixz="-1.56250248067259E-22"
        iyy="5.7279222490478E-07"
        iyz="2.13588113585916E-23"
        izz="8.32798685348821E-07" />
    </inertial>
    <visual>
      <origin
        xyz="0 0 0"
        rpy="0 0 0" />
      <geometry>
        <mesh
          filename="package://leg-2/meshes/L_R_1.STL" />
      </geometry>
      <material
        name="">
        <color
          rgba="1 1 1 1" />
      </material>
    </visual>
    <collision>
      <origin
        xyz="0 0 0"
        rpy="0 0 0" />
      <geometry>
        <mesh
          filename="package://leg-2/meshes/L_R_1.STL" />
      </geometry>
    </collision>
  </link>
  <joint
    name="J_R_1"
    type="continuous">
    <origin
      xyz="0.00500000000000005 0 0"
      rpy="1.5707963267949 0 -1.5707963267949" />
    <parent
      link="L_R_0" />
    <child
      link="L_R_1" />
    <axis
      xyz="1 0 0" />
  </joint>
  <link
    name="L_R_2">
    <inertial>
      <origin
        xyz="0.0829352552189959 0.00577871243284926 1.52655665885959E-16"
        rpy="0 0 0" />
      <mass
        value="0.0162098836233209" />
      <inertia
        ixx="2.40381887534248E-06"
        ixy="-6.16592737719073E-06"
        ixz="-6.04711054714986E-22"
        iyy="3.5339588835625E-05"
        iyz="1.07664232818176E-22"
        izz="3.74765154762597E-05" />
    </inertial>
    <visual>
      <origin
        xyz="0 0 0"
        rpy="0 0 0" />
      <geometry>
        <mesh
          filename="package://leg-2/meshes/L_R_2.STL" />
      </geometry>
      <material
        name="">
        <color
          rgba="1 1 1 1" />
      </material>
    </visual>
    <collision>
      <origin
        xyz="0 0 0"
        rpy="0 0 0" />
      <geometry>
        <mesh
          filename="package://leg-2/meshes/L_R_2.STL" />
      </geometry>
    </collision>
  </link>
  <joint
    name="J_R_2"
    type="continuous">
    <origin
      xyz="0 0.01 0"
      rpy="-3.14159265358979 0 1.5707963267949" />
    <parent
      link="L_R_1" />
    <child
      link="L_R_2" />
    <axis
      xyz="1 0 0" />
  </joint>
</robot>